<?xml version="1.0"?>
<robot xmlns:xacro="http://www.ros.org/wiki/xacro"
       name="aleph2">

  <xacro:include filename="$(find aleph2_description)/urdf/aleph2.gazebo" />
  <xacro:include filename="$(find aleph2_description)/urdf/materials.xacro" />

  <link name="base_link">
    <visual>
      <geometry>
        <mesh filename="package://aleph2_description/meshes/base.STL" />
      </geometry>
      <origin xyz="0 0 0" rpy="${pi/2} 0 ${pi/2}"/>
      <material name="base" />
    </visual>
    <visual>
      <geometry>
        <cylinder radius="0.02" length="0.12" />
      </geometry>
      <origin xyz="0.06 0.125 0.063" />
      <material name="motor">
        <color rgba="0 0 0.5 1"/>
      </material>
    </visual>
    <visual>
      <geometry>
        <cylinder radius="0.016" length="0.1" />
      </geometry>
      <origin xyz="0.151 0.175 0.053" />
      <material name="encoder">
        <color rgba="0 0.5 0 1"/>
      </material>
    </visual>
    <collision>
      <geometry>
        <box size="0.72 0.5 0.1"/>
      </geometry>
      <origin xyz="-0.08 0 0"/>
    </collision>
    <collision>
      <geometry>
        <box size="0.16 0.5 0.1"/>
      </geometry>
      <origin xyz="-0.06 0 0.09"/>
    </collision>
    <collision>
      <geometry>
        <cylinder radius="0.02" length="0.12" />
      </geometry>
      <origin xyz="0.06 0.125 0.063" />
    </collision>
    <collision>
      <geometry>
        <cylinder radius="0.016" length="0.1" />
      </geometry>
      <origin xyz="0.151 0.175 0.053" />
    </collision>
    <inertial>
      <origin xyz="-0.06700 0.00064 0.00551"/>
      <mass value="9.0" />
      <inertia ixx="0.23691" ixy="-0.00014" ixz="-0.00314" 
               iyy="0.23328" iyz="-0.00054" izz="0.40961" />
    </inertial>
  </link>

  <xacro:macro name="rocker" params="name">
    <link name="rocker_${name}_link">
      <visual>
        <geometry>
          <mesh filename="package://aleph2_description/meshes/rocker.STL"/>
        </geometry>
        <material name="rocker" />
      </visual>
      <collision>
        <geometry>
          <mesh filename="package://aleph2_description/meshes/rocker_collision.STL" />
        </geometry>
      </collision>
      <inertial>
        <origin xyz="0.00000 -0.01737 0.03763"/>
        <mass value="1.5" />
        <inertia ixx="0.01934" ixy="-0.00942" ixz="-0.00271" 
                 iyy="0.03716" iyz="0.00516"  izz="0.04409" />
      </inertial>
    </link>
  </xacro:macro>

  <xacro:macro name="wheel" params="name"> 
    <link name="wheel_${name}_link">
      <visual>
        <geometry>
          <mesh filename="package://aleph2_description/meshes/wheel.STL"/>
        </geometry>
        <material name="wheel" />
      </visual>
      <visual>
        <geometry>
          <cylinder radius="0.05" length="0.12"/>
        </geometry>
        <origin xyz="0 0 0" rpy="${pi/2} 0 0"/>
        <material name="piasta">
          <color rgba="0.5 0.5 0.5 1" />
        </material>
      </visual>
      <visual>
        <geometry>
          <cylinder radius="0.0055" length="0.15"/>
        </geometry>
        <origin xyz="0 0 0" rpy="${pi/2} 0 0"/>
        <material name="walek">
          <color rgba="0.7 0.7 0.7 1" />
        </material>
      </visual>
      <collision>
        <geometry>
          <cylinder radius="0.18" length="0.1" />
        </geometry>
        <origin xyz="0 0 0" rpy="${pi/2} 0 0"/>
      </collision>
      <collision>
        <geometry>
          <cylinder radius="0.007" length="0.15"/>
        </geometry>
        <origin xyz="0 0 0" rpy="${pi/2} 0 0"/>
      </collision>
      <inertial>
        <origin xyz="0.00000 0.00000 0.00000"/>
        <mass value="6.0" />
        <inertia ixx="0.03845" ixy="0.00000" ixz="0.00000" 
                 iyy="0.06495" iyz="0.00000" izz="0.03845" />
      </inertial>
    </link>
  </xacro:macro>

  <xacro:rocker name="R" />
  <xacro:rocker name="L" />

  <xacro:wheel name="FR" />
  <xacro:wheel name="RR" />
  <xacro:wheel name="FL" />
  <xacro:wheel name="RL" />

  <link name="manip_base_link">
    <visual>
      <geometry>
          <mesh filename="package://aleph2_description/meshes/manip_base.STL"/>
      </geometry>
      <origin rpy="${pi/2} 0 ${-pi/2}"/>
      <material name="manip" />
    </visual>
    <collision>
      <geometry>
        <cylinder radius="0.125" length="0.02" />
      </geometry>
      <origin xyz="0 0 0.01"/>
    </collision>
    <collision>
      <geometry>
        <cylinder radius="0.11" length="0.025" />
      </geometry>
      <origin xyz="0 0.017 0.09" rpy="${pi/2} 0 0"/>
    </collision>
    <collision>
      <geometry>
        <box size="0.1 0.15 0.15"/>
      </geometry>
      <origin xyz="0 0 0.075"/>
    </collision>
    <collision>
      <geometry>
        <box size="0.1 0.22 0.10"/>
      </geometry>
      <origin xyz="0 0 0.05"/>
    </collision>
    <inertial>
      <origin xyz="-0.00251 0.00769 0.05483"/>
      <mass value="2.0" />
      <inertia ixx="0.00845" ixy="-0.00007" ixz="-0.00023" 
               iyy="0.00892" iyz="0.00049"  izz="0.00862" />
    </inertial>
  </link>

  <link name="manip_shoulder_link">
    <visual>
      <geometry>
          <mesh filename="package://aleph2_description/meshes/manip_shoulder.STL"/>
      </geometry>
      <origin rpy="${pi} 0 0"/>
      <material name="manip" />
    </visual>
    <visual>
      <geometry>
        <cylinder radius="0.0225" length="0.122"/>
      </geometry>
      <origin xyz="0.082 0 0.106" rpy="0 0 0" />
      <material name="motor">
        <color rgba="0 0 0.5 1"/>
      </material> 
    </visual>
    <visual>
      <geometry>
        <cylinder radius="0.0225" length="0.122"/>
      </geometry>
      <origin xyz="0.2 0 0.106" rpy="0 0 0" />
      <material name="motor">
        <color rgba="0 0 0.5 1"/>
      </material> 
    </visual>
    <visual>
      <geometry>
        <cylinder radius="0.017" length="0.054"/>
      </geometry>
      <origin xyz="0.147 -0.005 0.072" rpy="0 0 0" />
      <material name="enkoder">
        <color rgba="0 0.5 0 1"/>
      </material> 
    </visual>
    <visual>
      <geometry>
        <cylinder radius="0.017" length="0.054"/>
      </geometry>
      <origin xyz="0.278 0 0.072" rpy="0 0 0" />
      <material name="enkoder">
        <color rgba="0 0.5 0 1"/>
      </material> 
    </visual>
    <collision>
      <geometry>
        <box size="0.4 0.07 0.1" />
      </geometry>
      <origin xyz="0.2 0.0 0" />
    </collision>
    <collision>
      <geometry>
        <cylinder radius="0.035" length="0.1"/>
      </geometry>
    </collision>
    <collision>
      <geometry>
        <cylinder radius="0.035" length="0.1"/>
      </geometry>
      <origin xyz="0.4 0 0"/>
    </collision>
    <collision>
      <geometry>
        <cylinder radius="0.0225" length="0.122"/>
      </geometry>
      <origin xyz="0.082 0 0.106" rpy="0 0 0" />
      <material name="motor">
        <color rgba="0 0 0.5 1"/>
      </material> 
    </collision>
    <collision>
      <geometry>
        <cylinder radius="0.0225" length="0.122"/>
      </geometry>
      <origin xyz="0.2 0 0.106" rpy="0 0 0" />
      <material name="motor">
        <color rgba="0 0 0.5 1"/>
      </material> 
    </collision>
    <collision>
      <geometry>
        <cylinder radius="0.017" length="0.054"/>
      </geometry>
      <origin xyz="0.147 -0.005 0.072" rpy="0 0 0" />
      <material name="enkoder">
        <color rgba="0 0.5 0 1"/>
      </material> 
    </collision>
    <collision>
      <geometry>
        <cylinder radius="0.017" length="0.054"/>
      </geometry>
      <origin xyz="0.278 0 0.072" rpy="0 0 0" />
      <material name="enkoder">
        <color rgba="0 0.5 0 1"/>
      </material> 
    </collision>
    <inertial>
      <origin xyz="0.20075 0.00074 0.00055"/>
      <mass value="3.0" />
      <inertia ixx="0.00612" ixy="-0.00012" ixz="0.00022" 
               iyy="0.04816" iyz="0.00000"  izz="0.04531" />
    </inertial>
  </link>

  <link name="manip_elbow_link">
    <visual>
      <geometry>
          <mesh filename="package://aleph2_description/meshes/manip_elbow.STL"/>
      </geometry>
      <origin rpy="0 ${pi/2} 0"/>
      <material name="manip" />
    </visual>
    <collision>
      <geometry>
        <box size="0.4 0.06 0.09" />
      </geometry>
      <origin xyz="0.2 0.0 0" />
    </collision>
    <collision>
      <geometry>
        <cylinder radius="0.03" length="0.09"/>
      </geometry>
      <origin xyz="0.4 0 0"/>
    </collision>
    <collision>
      <geometry>
        <cylinder radius="0.085" length="0.025"/>
      </geometry>
      <origin xyz="0 0 0.02"/>
    </collision>
    <inertial>
      <origin xyz="0.12196 0.00137 0.00713"/>
      <mass value="3.0" />
      <inertia ixx="0.00480" ixy="-0.00030" ixz="-0.00277" 
               iyy="0.05728" iyz="0.00004"  izz="0.05732" />
    </inertial>
  </link>

  <link name="manip_wrist_link">
    <visual>
      <geometry>
          <mesh filename="package://aleph2_description/meshes/manip_wrist.STL"/>
      </geometry>
      <origin rpy="0 ${pi/2} 0"/>
      <material name="manip" />
    </visual>
    <visual>
      <geometry>
        <cylinder radius="0.02" length="0.108"/>
      </geometry>
      <origin xyz="-0.03 0 0" rpy="0 ${pi/2} 0"/>
      <material name="motor">
        <color rgba="0 0 0.5 1"/>
      </material>
    </visual>
    <visual>
      <geometry>
        <box size="0.015 0.03 0.008"/>
      </geometry>
      <origin xyz="-0.088 0.005 0" rpy="0 ${pi/2} 0"/>
      <material name="enkoder">
        <color rgba="0 0.5 0 1"/>
      </material>
    </visual>
    <collision>
      <geometry>
        <box size="0.154 0.052 0.060"/>
      </geometry>
      <origin xyz="-0.016 0 0" rpy="0 0 0"/>
    </collision>
    <inertial>
      <origin xyz="-0.02500 0.00000 0.00000"/>
      <mass value="0.7" />
      <inertia ixx="0.00042" ixy="0.00000" ixz="0.00000" 
               iyy="0.00120" iyz="0.00000" izz="0.00112" />
    </inertial>
  </link> 

  <link name="manip_gripper_link">
    <visual>
      <geometry>
          <mesh filename="package://aleph2_description/meshes/manip_gripper.STL"/>
      </geometry>
      <origin rpy="0 ${pi/2} 0"/>
      <material name="manip" />
    </visual>
    <collision>
      <geometry>
        <box size="0.017 0.072 0.03"/>
      </geometry>
      <origin xyz="0.0085 0 0"/>
    </collision>
    <collision>
      <geometry>
        <box size="0.09 0.171 0.054"/>
      </geometry>
      <origin xyz="0.061 0 0"/>
    </collision>
    <collision>
      <geometry>
        <box size="0.049 0.068 0.089"/>
      </geometry>
      <origin xyz="0.0405 -0.1155 0.0175"/>
    </collision>
    <inertial>
      <origin xyz="0.04679 -0.03978 0.00393"/>
      <mass value="1.0" />
      <inertia ixx="0.00496" ixy="0.00022" ixz="-0.00002" 
               iyy="0.00108" iyz="-0.00036" izz="0.00535" />
    </inertial>
  </link>

  <link name="manip_jaw_L_link">
    <visual>
      <geometry>
        <mesh filename="package://aleph2_description/meshes/manip_jaw.STL" />
      </geometry>
      <origin rpy="${-pi/2} 0 ${pi/2}"/>
      <material name="manip" />
    </visual>
    <collision>
      <geometry>
        <box size="0.180 0.035 0.027" />
      </geometry>
      <origin xyz="0.09 0.0105 0"/>
    </collision>
    <inertial>
      <origin xyz="0.09230 0.00805 0.00000"/>
      <mass value="0.15" />
      <inertia ixx="0.00003" ixy="0.00005" ixz="0.00000" 
               iyy="0.00033" iyz="0.00000" izz="0.00033" />
    </inertial>
  </link>

  <link name="manip_jaw_R_link">
    <visual>
      <geometry>
        <mesh filename="package://aleph2_description/meshes/manip_jaw.STL" />
      </geometry>
      <origin rpy="${-pi/2} ${pi} ${pi/2}"/>
      <material name="manip" />
    </visual>
    <collision>
      <geometry>
        <box size="0.180 0.035 0.027" />
      </geometry>
      <origin xyz="0.09 -0.0105 0"/>
    </collision>
    <inertial>
      <origin xyz="0.09230 -0.00805 0.00000"/>
      <mass value="0.15" />
      <inertia ixx="0.00003" ixy="0.00005" ixz="0.00000" 
               iyy="0.00033" iyz="0.00000" izz="0.00033" />
    </inertial>
  </link>

  <link name="manip_effector_tip_link"/>

  <link name="mast_link">
    <visual>
      <geometry>
        <cylinder radius="0.02" length="1.3" />
      </geometry>
      <origin xyz="0 0 0.65" rpi="0 0 0"/>
      <material name="mast" />
    </visual>
    <collision>
      <geometry>
        <cylinder radius="0.03" length="1.3" />
      </geometry>
      <origin xyz="0 0 0.65" rpi="0 0 0"/>
    </collision>
    <collision>
      <geometry>
        <cylinder radius="0.1" length="0.7" />
      </geometry>
      <origin xyz="0 0 0.95" rpi="0 0 0"/>
    </collision>
    <inertial>
      <mass value="1.0" />
      <inertia ixx="1.0" ixy="0.0" ixz="0.0" iyy="1.0" iyz="0.0" izz="1.0" />
    </inertial>
  </link>

  <link name="zed_position">
    <visual>
      <origin xyz="0 0 0" rpy="0 0 0"/>
        <geometry>
          <mesh filename="package://aleph2_description/meshes/ZED.stl" />
        </geometry>
      <material name="light_grey">
        <color rgba="0.8 0.8 0.8 1"/>
      </material>
    </visual>
    <collision>
      <geometry>
        <box size="0.035 0.18 0.032"/>
      </geometry>
    </collision>
  </link>


  <!-- ROCKERS -->

  <joint name="rocker_R_joint" type="fixed">
    <parent link="base_link"/>
    <child link="rocker_R_link"/>
      <origin xyz="0 -0.375 0" rpy="${pi/2} 0 ${pi}"/>
  </joint>

  <joint name="rocker_L_joint" type="fixed">
    <parent link="base_link"/>
    <child link="rocker_L_link"/>
      <origin xyz="0 0.375 0" rpy="${pi/2} 0 0"/>
  </joint>

  <!-- WHEELS -->

  <joint name="wheel_FR_joint" type="continuous">
    <parent link="rocker_R_link"/>
    <child link="wheel_FR_link"/>
    <origin xyz="-0.418 -0.226 -0.07" rpy="${pi/2} 0 0" />
    <axis xyz="0 1 0"/>
    <dynamics damping="0.5" friction="0.2"/>
    <limit effort="20" velocity="25.0"/>
  </joint>

  <joint name="wheel_RR_joint" type="continuous">
    <parent link="rocker_R_link"/>
    <child link="wheel_RR_link"/>
    <origin xyz="0.418 -0.226 -0.07" rpy="${-pi/2} 0 0" />
    <axis xyz="0 -1 0"/>
    <dynamics damping="0.5" friction="0.2"/>
    <limit effort="20" velocity="25.0"/>
  </joint>

  <joint name="wheel_FL_joint" type="continuous">
    <parent link="rocker_L_link"/>
    <child link="wheel_FL_link"/>
    <origin xyz="0.418 -0.226 -0.07" rpy="${-pi/2} 0 0" />
    <axis xyz="0 1 0"/>
    <dynamics damping="0.5" friction="0.2"/>
    <limit effort="20" velocity="25.0"/>
  </joint>

  <joint name="wheel_RL_joint" type="continuous">
    <parent link="rocker_L_link"/>
    <child link="wheel_RL_link"/>
    <origin xyz="-0.418 -0.226 -0.07" rpy="${pi/2} 0 0" />
    <axis xyz="0 -1 0"/>
    <dynamics damping="0.5" friction="0.2"/>
    <limit effort="20" velocity="25.0"/>
  </joint>

  <!-- MANIP -->

  <joint name="manip_base_joint" type="continuous">
    <parent link="base_link"/>
    <child link="manip_base_link"/>
    <origin xyz="0.151 0.0035 0.032"/>
    <axis xyz="0 0 1"/>
    <limit effort="32000" velocity="0.15"/> 
    <dynamics damping="0.0" friction="0.1"/>
  </joint>

  <joint name="manip_shoulder_joint" type="revolute">
    <parent link="manip_base_link"/>
    <child link="manip_shoulder_link"/>
    <origin xyz="0 0 0.09" rpy="${pi/2} 0 0"/>
    <axis xyz="0 0 1" />
    <limit effort="32000" lower="0.0" upper="${pi}" velocity="0.3"/>
    <dynamics damping="0.0" friction="0.1"/>
  </joint>

  <joint name="manip_elbow_joint" type="revolute">
    <parent link="manip_shoulder_link"/>
    <child link="manip_elbow_link"/>
    <origin xyz="0.4 0 0" rpy="${pi} 0 0" />
    <axis xyz="0 0 -1" />
    <limit effort="32000" lower="-2.28" upper="2.43" velocity="0.5"/>
    <dynamics damping="0.0" friction="0.1"/>
  </joint>

  <joint name="manip_wrist_tilt_joint" type="revolute">
    <parent link="manip_elbow_link"/>
    <child link="manip_wrist_link"/>
    <origin xyz="0.4 0 0" />
    <axis xyz="0 0 -1" />
    <limit effort="32000" lower="-2.2" upper="2.2" velocity="0.5"/>
    <dynamics damping="0.0" friction="0.1"/>
  </joint>

  <joint name="manip_wrist_roll_joint" type="revolute">
    <parent link="manip_wrist_link"/>
    <child link="manip_gripper_link"/>
    <origin xyz="0.06 0 0" rpy="${-pi/2} 0 0"/>
    <axis xyz="-1 0 0" />
    <limit effort="32000" lower="${-pi}" upper="${pi}" velocity="0.5"/>
    <dynamics damping="0.0" friction="0.1"/>
  </joint>

  <joint name="manip_gripper_joint" type="prismatic">
    <parent link="manip_gripper_link"/>
    <child link="manip_jaw_L_link"/>
    <origin xyz="0.025 -0.03 0"/>
    <axis xyz="0 1 0" />
    <limit effort="150" lower="-0.033" upper="0" velocity="0.05"/>
    <dynamics damping="0.0" friction="0.1"/>
  </joint>

  <joint name="manip_gripper_joint_mimic" type="prismatic">
    <parent link="manip_gripper_link"/>
    <child link="manip_jaw_R_link"/>
    <origin xyz="0.025 0.03 0"/>
    <axis xyz="0 -1 0" />
    <mimic joint="manip_gripper_joint" />
    <limit effort="150" lower="-0.033" upper="0" velocity="0.05"/>
    <dynamics damping="0.0" friction="0.1"/>
  </joint>

  <joint name="manip_effector_tip_joint" type="fixed">
    <parent link="manip_gripper_link"/>
    <child link="manip_effector_tip_link"/>
    <origin xyz="0.20 0 0"/>
    <dynamics damping="0.0" friction="0.1"/>
  </joint>

  <!-- MASZT -->

  <joint name="mast_joint" type="fixed">
    <parent link="base_link" />
    <child link="mast_link" />
    <origin xyz="-0.22 0.25 -0.15"/>
  </joint>

  <!-- ZED -->

  <joint name="zed_camera_joint" type="fixed">
    <parent link="base_link"/>
    <child link="zed_position"/>
    <origin xyz="0.265 -0.16 0.015"/>
  </joint>

    
  <!-- TRASNMISSIONS -->

  <transmission name="wheel_FR_transmission">
    <type>transmission_interface/SimpleTransmission</type>
    <joint name="wheel_FR_joint">
      <hardwareInterface>hardware_interface/VelocityJointInterface</hardwareInterface>
    </joint>
    <actuator name="wheel_FR_actuator">
      <hardwareInterface>hardware_interface/VelocityJointInterface</hardwareInterface>
      <mechanicalReduction>1</mechanicalReduction>
    </actuator>
  </transmission>

  <transmission name="wheel_FL_transmission">
    <type>transmission_interface/SimpleTransmission</type>
    <joint name="wheel_FL_joint">
      <hardwareInterface>hardware_interface/VelocityJointInterface</hardwareInterface>
    </joint>
    <actuator name="wheel_FL_actuator">
      <hardwareInterface>hardware_interface/VelocityJointInterface</hardwareInterface>
      <mechanicalReduction>1</mechanicalReduction>
    </actuator>
  </transmission>

  <transmission name="wheel_RR_transmission">
    <type>transmission_interface/SimpleTransmission</type>
    <joint name="wheel_RR_joint">
      <hardwareInterface>hardware_interface/VelocityJointInterface</hardwareInterface>
    </joint>
    <actuator name="wheel_RR_actuator">
      <hardwareInterface>hardware_interface/VelocityJointInterface</hardwareInterface>
      <mechanicalReduction>1</mechanicalReduction>
    </actuator>
  </transmission>

  <transmission name="wheel_RL_transmission">
    <type>transmission_interface/SimpleTransmission</type>
    <joint name="wheel_RL_joint">
      <hardwareInterface>hardware_interface/VelocityJointInterface</hardwareInterface>
    </joint>
    <actuator name="wheel_RL_actuator">
      <hardwareInterface>hardware_interface/VelocityJointInterface</hardwareInterface>
      <mechanicalReduction>1</mechanicalReduction>
    </actuator>
  </transmission>

  <transmission name="manip_base_transmission">
    <type>transmission_interface/SimpleTransmission</type>
    <joint name="manip_base_joint">
      <hardwareInterface>hardware_interface/EffortJointInterface</hardwareInterface>
    </joint>
    <actuator name="manip_base_actuator">
      <hardwareInterface>hardware_interface/EffortJointInterface</hardwareInterface>
      <mechanicalReduction>1</mechanicalReduction>
    </actuator>
  </transmission>

  <transmission name="manip_shoulder_transmission">
    <type>transmission_interface/SimpleTransmission</type>
    <joint name="manip_shoulder_joint">
      <hardwareInterface>hardware_interface/EffortJointInterface</hardwareInterface>
    </joint>
    <actuator name="manip_shoulder_actuator">
      <hardwareInterface>hardware_interface/EffortJointInterface</hardwareInterface>
      <mechanicalReduction>1</mechanicalReduction>
    </actuator>
  </transmission>

  <transmission name="manip_elbow_transmission">
    <type>transmission_interface/SimpleTransmission</type>
    <joint name="manip_elbow_joint">
      <hardwareInterface>hardware_interface/EffortJointInterface</hardwareInterface>
    </joint>
    <actuator name="manip_elbow_actuator">
      <hardwareInterface>hardware_interface/EffortJointInterface</hardwareInterface>
      <mechanicalReduction>1</mechanicalReduction>
    </actuator>
  </transmission>

  <transmission name="manip_wrist_tilt_transmission">
    <type>transmission_interface/SimpleTransmission</type>
    <joint name="manip_wrist_tilt_joint">
      <hardwareInterface>hardware_interface/EffortJointInterface</hardwareInterface>
    </joint>
    <actuator name="manip_wrist_tilt_actuator">
      <hardwareInterface>hardware_interface/EffortJointInterface</hardwareInterface>
      <mechanicalReduction>1</mechanicalReduction>
    </actuator>
  </transmission>

  <transmission name="manip_wrist_roll_transmission">
    <type>transmission_interface/SimpleTransmission</type>
    <joint name="manip_wrist_roll_joint">
      <hardwareInterface>hardware_interface/EffortJointInterface</hardwareInterface>
    </joint>
    <actuator name="manip_wrist_roll_actuator">
      <hardwareInterface>hardware_interface/EffortJointInterface</hardwareInterface>
      <mechanicalReduction>1</mechanicalReduction>
    </actuator>
  </transmission>

  <transmission name="manip_gripper_transmission">
    <type>transmission_interface/SimpleTransmission</type>
    <joint name="manip_gripper_joint">
      <hardwareInterface>hardware_interface/EffortJointInterface</hardwareInterface>
    </joint>
    <actuator name="manip_gripper_actuator">
      <hardwareInterface>hardware_interface/EffortJointInterface</hardwareInterface>
      <mechanicalReduction>1</mechanicalReduction>
    </actuator>
  </transmission>

  <!-- <link name="world"/>

  <joint name="fixed" type="fixed">
    <parent link="world"/>
    <child link="base_link"/>
    <origin xyz="0.0 0.0 2.0"/>
  </joint> -->

</robot>
