<?xml version="1.0"?>
<robot xmlns:xacro="http://www.ros.org/wiki/xacro"
       name="aleph2">


  <xacro:include filename="$(find aleph2_description)/urdf/aleph2.gazebo" />

  <material name="lazik">
    <color rgba="0.3 0.3 0.3 1"/>
  </material>
  <material name="chromosom">
    <color rgba="0 0 0.8 1"/>
  </material>
  <material name="kolo">
    <texture filename="package://aleph_viz/textures/wheel.jpg" />
  </material>
  <material name="manip">
    <color rgba="0.4 0.4 0.4 1"/>
  </material>
  <material name="maszt">
    <color rgba="0.8 0.8 0.8 1" />
  </material>

  <xacro:macro name="chromosom" params="name">
    <link name="chromosom_${name}">
      <visual>
        <geometry>
          <mesh filename="package://aleph_viz/meshes/chromosom.STL"/>
        </geometry>
        <material name="chromosom" />
      </visual>
      <collision>
        <geometry>
          <mesh filename="package://aleph_viz/meshes/chromosom_collision.STL" />
        </geometry>
      </collision>
      <inertial>
        <origin xyz="0.00000 -0.01737 0.03763"/>
        <mass value="1.5" />
        <inertia ixx="0.01934" ixy="-0.00942" ixz="-0.00271" 
                 iyy="0.03716" iyz="0.00516"  izz="0.04409" />
      </inertial>
    </link>
  </xacro:macro>

  <xacro:macro name="kolo" params="name"> 
    <link name="kolo_${name}">
      <visual>
        <geometry>
          <mesh filename="package://aleph_viz/meshes/kolo.STL"/>
        </geometry>
        <material name="kolo" />
      </visual>
      <visual>
        <geometry>
          <cylinder radius="0.05" length="0.12"/>
        </geometry>
        <origin xyz="0 0 0" rpy="${pi/2} 0 0"/>
        <material name="piasta">
          <color rgba="0.5 0.5 0.5 1" />
        </material>
      </visual>
      <visual>
        <geometry>
          <cylinder radius="0.0055" length="0.15"/>
        </geometry>
        <origin xyz="0 0 0" rpy="${pi/2} 0 0"/>
        <material name="walek">
          <color rgba="0.7 0.7 0.7 1" />
        </material>
      </visual>
      <collision>
        <geometry>
          <cylinder radius="0.18" length="0.1" />
        </geometry>
        <origin xyz="0 0 0" rpy="${pi/2} 0 0"/>
      </collision>
      <collision>
        <geometry>
          <cylinder radius="0.007" length="0.15"/>
        </geometry>
        <origin xyz="0 0 0" rpy="${pi/2} 0 0"/>
      </collision>
      <inertial>
        <origin xyz="0.00000 0.00000 0.00000"/>
        <mass value="6.0" />
        <inertia ixx="0.03845" ixy="0.00000" ixz="0.00000" 
                 iyy="0.06495" iyz="0.00000" izz="0.03845" />
      </inertial>
    </link>
  </xacro:macro>

  <link name="base_link">
    <visual>
      <geometry>
        <mesh filename="package://aleph_viz/meshes/lazik.STL" />
      </geometry>
      <origin xyz="0 0 0" rpy="${pi/2} 0 ${pi/2}"/>
      <material name="lazik" />
    </visual>
    <visual>
      <geometry>
        <cylinder radius="0.02" length="0.12" />
      </geometry>
      <origin xyz="0.06 0.125 0.063" />
      <material name="silnik">
        <color rgba="0 0 0.5 1"/>
      </material>
    </visual>
    <visual>
      <geometry>
        <cylinder radius="0.016" length="0.1" />
      </geometry>
      <origin xyz="0.151 0.175 0.053" />
      <material name="enkoder">
        <color rgba="0 0.5 0 1"/>
      </material>
    </visual>
    <collision>
      <geometry>
        <box size="0.72 0.5 0.1"/>
      </geometry>
      <origin xyz="-0.08 0 0"/>
    </collision>
    <collision>
      <geometry>
        <box size="0.16 0.5 0.1"/>
      </geometry>
      <origin xyz="-0.06 0 0.09"/>
    </collision>
    <collision>
      <geometry>
        <cylinder radius="0.02" length="0.12" />
      </geometry>
      <origin xyz="0.06 0.125 0.063" />
    </collision>
    <collision>
      <geometry>
        <cylinder radius="0.016" length="0.1" />
      </geometry>
      <origin xyz="0.151 0.175 0.053" />
    </collision>
    <inertial>
      <origin xyz="-0.06700 0.00064 0.00551"/>
      <mass value="9.0" />
      <inertia ixx="0.23691" ixy="-0.00014" ixz="-0.00314" 
               iyy="0.23328" iyz="-0.00054" izz="0.40961" />
    </inertial>
  </link>

  <xacro:chromosom name="R" />
  <xacro:chromosom name="L" />

  <xacro:kolo name="FR" />
  <xacro:kolo name="RR" />
  <xacro:kolo name="FL" />
  <xacro:kolo name="RL" />

  <!-- <link name="manip_support">
    <inertial>
      <mass value="0.0" />
      <inertia ixx="1.0" ixy="0.0" ixz="0.0" iyy="1.0" iyz="0.0" izz="1.0" />
    </inertial>
  </link> -->

  <link name="manip_base">
    <visual>
      <geometry>
          <mesh filename="package://aleph_viz/meshes/A.STL"/>
      </geometry>
      <origin rpy="${pi/2} 0 ${-pi/2}"/>
      <material name="manip" />
    </visual>
    <collision>
      <geometry>
        <cylinder radius="0.125" length="0.02" />
      </geometry>
      <origin xyz="0 0 0.01"/>
    </collision>
    <collision>
      <geometry>
        <cylinder radius="0.11" length="0.025" />
      </geometry>
      <origin xyz="0 0.017 0.09" rpy="${pi/2} 0 0"/>
    </collision>
    <collision>
      <geometry>
        <box size="0.1 0.15 0.15"/>
      </geometry>
      <origin xyz="0 0 0.075"/>
    </collision>
    <collision>
      <geometry>
        <box size="0.1 0.22 0.10"/>
      </geometry>
      <origin xyz="0 0 0.05"/>
    </collision>
    <inertial>
      <origin xyz="-0.00251 0.00769 0.05483"/>
      <mass value="2.0" />
      <inertia ixx="0.00845" ixy="-0.00007" ixz="-0.00023" 
               iyy="0.00892" iyz="0.00049"  izz="0.00862" />
    </inertial>
  </link>

  <link name="manip_B">
    <visual>
      <geometry>
          <mesh filename="package://aleph_viz/meshes/B.STL"/>
      </geometry>
      <origin rpy="${pi} 0 0"/>
      <material name="manip" />
    </visual>
    <visual>
      <geometry>
        <cylinder radius="0.0225" length="0.122"/>
      </geometry>
      <origin xyz="0.082 0 0.106" rpy="0 0 0" />
      <material name="silnik">
        <color rgba="0 0 0.5 1"/>
      </material> 
    </visual>
    <visual>
      <geometry>
        <cylinder radius="0.0225" length="0.122"/>
      </geometry>
      <origin xyz="0.2 0 0.106" rpy="0 0 0" />
      <material name="silnik">
        <color rgba="0 0 0.5 1"/>
      </material> 
    </visual>
    <visual>
      <geometry>
        <cylinder radius="0.017" length="0.054"/>
      </geometry>
      <origin xyz="0.147 -0.005 0.072" rpy="0 0 0" />
      <material name="enkoder">
        <color rgba="0 0.5 0 1"/>
      </material> 
    </visual>
    <visual>
      <geometry>
        <cylinder radius="0.017" length="0.054"/>
      </geometry>
      <origin xyz="0.278 0 0.072" rpy="0 0 0" />
      <material name="enkoder">
        <color rgba="0 0.5 0 1"/>
      </material> 
    </visual>
    <collision>
      <geometry>
        <box size="0.4 0.07 0.1" />
      </geometry>
      <origin xyz="0.2 0.0 0" />
    </collision>
    <collision>
      <geometry>
        <cylinder radius="0.035" length="0.1"/>
      </geometry>
    </collision>
    <collision>
      <geometry>
        <cylinder radius="0.035" length="0.1"/>
      </geometry>
      <origin xyz="0.4 0 0"/>
    </collision>
    <collision>
      <geometry>
        <cylinder radius="0.0225" length="0.122"/>
      </geometry>
      <origin xyz="0.082 0 0.106" rpy="0 0 0" />
      <material name="silnik">
        <color rgba="0 0 0.5 1"/>
      </material> 
    </collision>
    <collision>
      <geometry>
        <cylinder radius="0.0225" length="0.122"/>
      </geometry>
      <origin xyz="0.2 0 0.106" rpy="0 0 0" />
      <material name="silnik">
        <color rgba="0 0 0.5 1"/>
      </material> 
    </collision>
    <collision>
      <geometry>
        <cylinder radius="0.017" length="0.054"/>
      </geometry>
      <origin xyz="0.147 -0.005 0.072" rpy="0 0 0" />
      <material name="enkoder">
        <color rgba="0 0.5 0 1"/>
      </material> 
    </collision>
    <collision>
      <geometry>
        <cylinder radius="0.017" length="0.054"/>
      </geometry>
      <origin xyz="0.278 0 0.072" rpy="0 0 0" />
      <material name="enkoder">
        <color rgba="0 0.5 0 1"/>
      </material> 
    </collision>
    <inertial>
      <origin xyz="0.20075 0.00074 0.00055"/>
      <mass value="3.0" />
      <inertia ixx="0.00612" ixy="-0.00012" ixz="0.00022" 
               iyy="0.04816" iyz="0.00000"  izz="0.04531" />
    </inertial>
  </link>

  <link name="manip_C">
    <visual>
      <geometry>
          <mesh filename="package://aleph_viz/meshes/C.STL"/>
      </geometry>
      <origin rpy="0 ${pi/2} 0"/>
      <material name="manip" />
    </visual>
    <collision>
      <geometry>
        <box size="0.4 0.06 0.09" />
      </geometry>
      <origin xyz="0.2 0.0 0" />
    </collision>
    <collision>
      <geometry>
        <cylinder radius="0.03" length="0.09"/>
      </geometry>
      <origin xyz="0.4 0 0"/>
    </collision>
    <collision>
      <geometry>
        <cylinder radius="0.085" length="0.025"/>
      </geometry>
      <origin xyz="0 0 0.02"/>
    </collision>
    <inertial>
      <origin xyz="0.12196 0.00137 0.00713"/>
      <mass value="3.0" />
      <inertia ixx="0.00480" ixy="-0.00030" ixz="-0.00277" 
               iyy="0.05728" iyz="0.00004"  izz="0.05732" />
    </inertial>
  </link>

  <link name="manip_D">
    <visual>
      <geometry>
          <mesh filename="package://aleph_viz/meshes/D.STL"/>
      </geometry>
      <origin rpy="0 ${pi/2} 0"/>
      <material name="manip" />
    </visual>
    <visual>
      <geometry>
        <cylinder radius="0.02" length="0.108"/>
      </geometry>
      <origin xyz="-0.03 0 0" rpy="0 ${pi/2} 0"/>
      <material name="silnik">
        <color rgba="0 0 0.5 1"/>
      </material>
    </visual>
    <visual>
      <geometry>
        <box size="0.015 0.03 0.008"/>
      </geometry>
      <origin xyz="-0.088 0.005 0" rpy="0 ${pi/2} 0"/>
      <material name="enkoder">
        <color rgba="0 0.5 0 1"/>
      </material>
    </visual>
    <collision>
      <geometry>
        <box size="0.154 0.052 0.060"/>
      </geometry>
      <origin xyz="-0.016 0 0" rpy="0 0 0"/>
    </collision>
    <inertial>
      <origin xyz="-0.02500 0.00000 0.00000"/>
      <mass value="0.7" />
      <inertia ixx="0.00042" ixy="0.00000" ixz="0.00000" 
               iyy="0.00120" iyz="0.00000" izz="0.00112" />
    </inertial>
  </link> 

  <link name="manip_efector">
    <visual>
      <geometry>
          <mesh filename="package://aleph_viz/meshes/efector.STL"/>
      </geometry>
      <origin rpy="0 ${pi/2} 0"/>
      <material name="manip" />
    </visual>
    <collision>
      <geometry>
        <box size="0.017 0.072 0.03"/>
      </geometry>
      <origin xyz="0.0085 0 0"/>
    </collision>
    <collision>
      <geometry>
        <box size="0.09 0.171 0.054"/>
      </geometry>
      <origin xyz="0.061 0 0"/>
    </collision>
    <collision>
      <geometry>
        <box size="0.049 0.068 0.089"/>
      </geometry>
      <origin xyz="0.0405 -0.1155 0.0175"/>
    </collision>
    <inertial>
      <origin xyz="0.04679 -0.03978 0.00393"/>
      <mass value="1.0" />
      <inertia ixx="0.00496" ixy="0.00022" ixz="-0.00002" 
               iyy="0.00108" iyz="-0.00036" izz="0.00535" />
    </inertial>
  </link>

  <link name="manip_jaw_L">
    <visual>
      <geometry>
        <mesh filename="package://aleph_viz/meshes/jaw.STL" />
      </geometry>
      <origin rpy="${-pi/2} 0 ${pi/2}"/>
      <material name="manip" />
    </visual>
    <collision>
      <geometry>
        <box size="0.180 0.035 0.027" />
      </geometry>
      <origin xyz="0.09 0.0105 0"/>
    </collision>
    <inertial>
      <origin xyz="0.09230 0.00805 0.00000"/>
      <mass value="0.15" />
      <inertia ixx="0.00003" ixy="0.00005" ixz="0.00000" 
               iyy="0.00033" iyz="0.00000" izz="0.00033" />
    </inertial>
  </link>

  <link name="manip_jaw_R">
    <visual>
      <geometry>
        <mesh filename="package://aleph_viz/meshes/jaw.STL" />
      </geometry>
      <origin rpy="${-pi/2} ${pi} ${pi/2}"/>
      <material name="manip" />
    </visual>
    <collision>
      <geometry>
        <box size="0.180 0.035 0.027" />
      </geometry>
      <origin xyz="0.09 -0.0105 0"/>
    </collision>
    <inertial>
      <origin xyz="0.09230 -0.00805 0.00000"/>
      <mass value="0.15" />
      <inertia ixx="0.00003" ixy="0.00005" ixz="0.00000" 
               iyy="0.00033" iyz="0.00000" izz="0.00033" />
    </inertial>
  </link>

  <link name="efector_tip"/>

  <link name="maszt">
    <visual>
      <geometry>
        <cylinder radius="0.02" length="1.3" />
      </geometry>
      <origin xyz="0 0 0.65" rpi="0 0 0"/>
      <material name="maszt" />
    </visual>
    <collision>
      <geometry>
        <cylinder radius="0.03" length="1.3" />
      </geometry>
      <origin xyz="0 0 0.65" rpi="0 0 0"/>
    </collision>
    <collision>
      <geometry>
        <cylinder radius="0.1" length="0.7" />
      </geometry>
      <origin xyz="0 0 0.95" rpi="0 0 0"/>
    </collision>
    <inertial>
      <mass value="1.0" />
      <inertia ixx="1.0" ixy="0.0" ixz="0.0" iyy="1.0" iyz="0.0" izz="1.0" />
    </inertial>
  </link>

  <link name="zed_position">
    <visual>
      <origin xyz="0 0 0" rpy="0 0 0"/>
        <geometry>
          <mesh filename="package://aleph_viz/meshes/ZED.stl" />
        </geometry>
      <material name="light_grey">
        <color rgba="0.8 0.8 0.8 1"/>
      </material>
    </visual>
    <collision>
      <geometry>
        <box size="0.035 0.18 0.032"/>
      </geometry>
    </collision>
    <inertial>
      <mass value="1.0" />
      <inertia ixx="1.0" ixy="0.0" ixz="0.0" iyy="1.0" iyz="0.0" izz="1.0" />
    </inertial>
  </link>



  <!-- CHROMOSOMY -->

  <joint name="chromosom_R_to_base" type="fixed">
    <parent link="base_link"/>
    <child link="chromosom_R"/>
      <origin xyz="0 -0.375 0" rpy="${pi/2} 0 ${pi}"/>
  </joint>

  <joint name="chromosom_L_to_base" type="fixed">
    <parent link="base_link"/>
    <child link="chromosom_L"/>
      <origin xyz="0 0.375 0" rpy="${pi/2} 0 0"/>
  </joint>

  <!-- KOLA -->

  <joint name="kolo_FR_to_chromosom_R" type="continuous">
    <parent link="chromosom_R"/>
    <child link="kolo_FR"/>
    <origin xyz="-0.418 -0.226 -0.07" rpy="${pi/2} 0 0" />
    <axis xyz="0 1 0"/>
  </joint>

  <joint name="kolo_RR_to_chromosom_R" type="continuous">
    <parent link="chromosom_R"/>
    <child link="kolo_RR"/>
    <origin xyz="0.418 -0.226 -0.07" rpy="${-pi/2} 0 0" />
    <axis xyz="0 -1 0"/>
  </joint>

  <joint name="kolo_FL_to_chromosom_L" type="continuous">
    <parent link="chromosom_L"/>
    <child link="kolo_FL"/>
    <origin xyz="0.418 -0.226 -0.07" rpy="${-pi/2} 0 0" />
    <axis xyz="0 1 0"/>
  </joint>

  <joint name="kolo_RL_to_chromosom_L" type="continuous">
    <parent link="chromosom_L"/>
    <child link="kolo_RL"/>
    <origin xyz="-0.418 -0.226 -0.07" rpy="${pi/2} 0 0" />
    <axis xyz="0 -1 0"/>
  </joint>

  <!-- MANIP -->

  <!-- <joint name="support_to_base" type="fixed">
    <parent link="base_link"/>
    <child link="manip_support"/>
    <origin xyz="0.151 0.0035 0.0"/>
  </joint> -->

  <joint name="base_to_frame" type="continuous">
    <parent link="base_link"/>
    <child link="manip_base"/>
    <origin xyz="0.151 0.0035 0.032"/>
    <axis xyz="0 0 1"/>
    <limit effort="32000" velocity="0.15"/> 
    <dynamics damping="10" friction="0.1"/>
  </joint>

  <joint name="B_to_base" type="revolute">
    <parent link="manip_base"/>
    <child link="manip_B"/>
    <origin xyz="0 0 0.09" rpy="${pi/2} 0 0"/>
    <axis xyz="0 0 1" />
    <limit effort="32000" lower="0.0" upper="3.14" velocity="0.3"/>
    <dynamics damping="10" friction="0.1"/>
  </joint>

  <joint name="C_to_B" type="revolute">
    <parent link="manip_B"/>
    <child link="manip_C"/>
    <origin xyz="0.4 0 0" rpy="${pi} 0 0" />
    <axis xyz="0 0 -1" />
    <limit effort="32000" lower="-2.28" upper="2.43" velocity="0.5"/>
    <dynamics damping="10" friction="0.1"/>
  </joint>

  <joint name="efector_to_C" type="revolute">
    <parent link="manip_C"/>
    <child link="manip_D"/>
    <origin xyz="0.4 0 0" />
    <axis xyz="0 0 -1" />
    <limit effort="32000" lower="-2.2" upper="2.2" velocity="0.5"/>
    <dynamics damping="10" friction="0.1"/>
  </joint>

  <joint name="efector_roll" type="revolute">
    <parent link="manip_D"/>
    <child link="manip_efector"/>
    <origin xyz="0.06 0 0" rpy="${-pi/2} 0 0"/>
    <axis xyz="-1 0 0" />
    <limit effort="32000" lower="${-pi}" upper="${pi}" velocity="0.5"/>
    <dynamics damping="10" friction="0.1"/>
  </joint>

  <joint name="efector_grip" type="prismatic">
    <parent link="manip_efector"/>
    <child link="manip_jaw_L"/>
    <origin xyz="0.025 -0.03 0"/>
    <axis xyz="0 1 0" />
    <limit effort="150" lower="-0.033" upper="0" velocity="0.05"/>
    <dynamics damping="10" friction="0.1"/>
  </joint>

  <joint name="efector_grip_mimic" type="prismatic">
    <parent link="manip_efector"/>
    <child link="manip_jaw_R"/>
    <origin xyz="0.025 0.03 0"/>
    <axis xyz="0 -1 0" />
    <mimic joint="efector_grip" />
    <limit effort="150" lower="-0.033" upper="0" velocity="0.05"/>
    <dynamics damping="10" friction="0.1"/>
  </joint>

  <joint name="efector_tip_to_manip_efector" type="fixed">
    <parent link="manip_efector"/>
    <child link="efector_tip"/>
    <origin xyz="0.20 0 0"/>
    <dynamics damping="10" friction="0.1"/>
  </joint>

  <!-- MASZT -->

  <joint name="maszt_to_base" type="fixed">
    <parent link="base_link" />
    <child link="maszt" />
    <origin xyz="-0.22 0.25 -0.15"/>
  </joint>

  <!-- ZED -->

  <joint name="zed_camera_to_base" type="fixed">
    <parent link="base_link"/>
    <child link="zed_position"/>
    <origin xyz="0.265 -0.16 0.015"/>
  </joint>

    
  <transmission name="kolo_FR_transmission">
    <type>transmission_interface/SimpleTransmission</type>
    <joint name="kolo_FR_to_chromosom_R">
      <hardwareInterface>hardware_interface/VelocityJointInterface</hardwareInterface>
    </joint>
    <actuator name="kolo_FR_actuator">
      <hardwareInterface>hardware_interface/VelocityJointInterface</hardwareInterface>
      <mechanicalReduction>1</mechanicalReduction>
    </actuator>
  </transmission>

  <transmission name="kolo_FL_transmission">
    <type>transmission_interface/SimpleTransmission</type>
    <joint name="kolo_FL_to_chromosom_L">
      <hardwareInterface>hardware_interface/VelocityJointInterface</hardwareInterface>
    </joint>
    <actuator name="kolo_FL_actuator">
      <hardwareInterface>hardware_interface/VelocityJointInterface</hardwareInterface>
      <mechanicalReduction>1</mechanicalReduction>
    </actuator>
  </transmission>

  <transmission name="kolo_RR_transmission">
    <type>transmission_interface/SimpleTransmission</type>
    <joint name="kolo_RR_to_chromosom_R">
      <hardwareInterface>hardware_interface/VelocityJointInterface</hardwareInterface>
    </joint>
    <actuator name="kolo_RR_actuator">
      <hardwareInterface>hardware_interface/VelocityJointInterface</hardwareInterface>
      <mechanicalReduction>1</mechanicalReduction>
    </actuator>
  </transmission>

  <transmission name="kolo_RL_transmission">
    <type>transmission_interface/SimpleTransmission</type>
    <joint name="kolo_RL_to_chromosom_L">
      <hardwareInterface>hardware_interface/VelocityJointInterface</hardwareInterface>
    </joint>
    <actuator name="kolo_RL_actuator">
      <hardwareInterface>hardware_interface/VelocityJointInterface</hardwareInterface>
      <mechanicalReduction>1</mechanicalReduction>
    </actuator>
  </transmission>

  <transmission name="base_to_frame_transmission">
    <type>transmission_interface/SimpleTransmission</type>
    <joint name="base_to_frame">
      <hardwareInterface>hardware_interface/EffortJointInterface</hardwareInterface>
    </joint>
    <actuator name="base_to_frame_actuator">
      <hardwareInterface>hardware_interface/EffortJointInterface</hardwareInterface>
      <mechanicalReduction>1</mechanicalReduction>
    </actuator>
  </transmission>

  <transmission name="B_to_base_transmission">
    <type>transmission_interface/SimpleTransmission</type>
    <joint name="B_to_base">
      <hardwareInterface>hardware_interface/EffortJointInterface</hardwareInterface>
    </joint>
    <actuator name="B_to_base_actuator">
      <hardwareInterface>hardware_interface/EffortJointInterface</hardwareInterface>
      <mechanicalReduction>1</mechanicalReduction>
    </actuator>
  </transmission>

  <transmission name="C_to_B_transmission">
    <type>transmission_interface/SimpleTransmission</type>
    <joint name="C_to_B">
      <hardwareInterface>hardware_interface/EffortJointInterface</hardwareInterface>
    </joint>
    <actuator name="C_to_B_actuator">
      <hardwareInterface>hardware_interface/EffortJointInterface</hardwareInterface>
      <mechanicalReduction>1</mechanicalReduction>
    </actuator>
  </transmission>

  <transmission name="efector_to_C_transmission">
    <type>transmission_interface/SimpleTransmission</type>
    <joint name="efector_to_C">
      <hardwareInterface>hardware_interface/EffortJointInterface</hardwareInterface>
    </joint>
    <actuator name="efector_to_C_actuator">
      <hardwareInterface>hardware_interface/EffortJointInterface</hardwareInterface>
      <mechanicalReduction>1</mechanicalReduction>
    </actuator>
  </transmission>

  <transmission name="efector_roll_transmission">
    <type>transmission_interface/SimpleTransmission</type>
    <joint name="efector_roll">
      <hardwareInterface>hardware_interface/EffortJointInterface</hardwareInterface>
    </joint>
    <actuator name="efector_roll_actuator">
      <hardwareInterface>hardware_interface/EffortJointInterface</hardwareInterface>
      <mechanicalReduction>1</mechanicalReduction>
    </actuator>
  </transmission>

  <transmission name="efector_grip_transmission">
    <type>transmission_interface/SimpleTransmission</type>
    <joint name="efector_grip">
      <hardwareInterface>hardware_interface/EffortJointInterface</hardwareInterface>
    </joint>
    <actuator name="efector_grip_actuator">
      <hardwareInterface>hardware_interface/EffortJointInterface</hardwareInterface>
      <mechanicalReduction>1</mechanicalReduction>
    </actuator>
  </transmission>

</robot>
